[2025-08-08T15:03:47.885+0700] {taskinstance.py:1159} INFO - Dependencies all met for dep_context=non-requeueable deps ti=<TaskInstance: ekstrak_pdf_dag.insert_to_milvus manual__2025-08-07T09:49:30.214499+00:00 [queued]>
[2025-08-08T15:03:47.911+0700] {taskinstance.py:1159} INFO - Dependencies all met for dep_context=requeueable deps ti=<TaskInstance: ekstrak_pdf_dag.insert_to_milvus manual__2025-08-07T09:49:30.214499+00:00 [queued]>
[2025-08-08T15:03:47.911+0700] {taskinstance.py:1361} INFO - Starting attempt 1 of 1
[2025-08-08T15:03:47.963+0700] {taskinstance.py:1382} INFO - Executing <Task(PythonOperator): insert_to_milvus> on 2025-08-07 09:49:30.214499+00:00
[2025-08-08T15:03:47.995+0700] {standard_task_runner.py:57} INFO - Started process 88673 to run task
[2025-08-08T15:03:48.116+0700] {standard_task_runner.py:84} INFO - Running: ['airflow', 'tasks', 'run', 'ekstrak_pdf_dag', 'insert_to_milvus', 'manual__2025-08-07T09:49:30.214499+00:00', '--job-id', '25', '--raw', '--subdir', 'DAGS_FOLDER/etl.py', '--cfg-path', '/tmp/tmps8d7mlw2']
[2025-08-08T15:03:48.120+0700] {standard_task_runner.py:85} INFO - Job 25: Subtask insert_to_milvus
[2025-08-08T15:03:49.138+0700] {task_command.py:416} INFO - Running <TaskInstance: ekstrak_pdf_dag.insert_to_milvus manual__2025-08-07T09:49:30.214499+00:00 [running]> on host dwmhr.localdomain
[2025-08-08T15:03:49.771+0700] {taskinstance.py:1662} INFO - Exporting env vars: AIRFLOW_CTX_DAG_OWNER='airflow' AIRFLOW_CTX_DAG_ID='ekstrak_pdf_dag' AIRFLOW_CTX_TASK_ID='insert_to_milvus' AIRFLOW_CTX_EXECUTION_DATE='2025-08-07T09:49:30.214499+00:00' AIRFLOW_CTX_TRY_NUMBER='1' AIRFLOW_CTX_DAG_RUN_ID='manual__2025-08-07T09:49:30.214499+00:00'
[2025-08-08T15:04:00.448+0700] {taskinstance.py:1937} ERROR - Task failed with exception
Traceback (most recent call last):
  File "/home/dwmhr/pln/venv/lib/python3.10/site-packages/airflow/operators/python.py", line 192, in execute
    return_value = self.execute_callable()
  File "/home/dwmhr/pln/venv/lib/python3.10/site-packages/airflow/operators/python.py", line 209, in execute_callable
    return self.python_callable(*self.op_args, **self.op_kwargs)
  File "/home/dwmhr/pln/scripts/insert_to_milvus.py", line 30, in insert_to_milvus
    connections.connect("default", host="localhost", port="19530")
  File "/home/dwmhr/pln/venv/lib/python3.10/site-packages/pymilvus/orm/connections.py", line 459, in connect
    connect_milvus(**kwargs, user=user, password=password, token=token, db_name=db_name)
  File "/home/dwmhr/pln/venv/lib/python3.10/site-packages/pymilvus/orm/connections.py", line 420, in connect_milvus
    raise e from e
  File "/home/dwmhr/pln/venv/lib/python3.10/site-packages/pymilvus/orm/connections.py", line 412, in connect_milvus
    gh._wait_for_channel_ready(timeout=timeout)
  File "/home/dwmhr/pln/venv/lib/python3.10/site-packages/pymilvus/client/grpc_handler.py", line 162, in _wait_for_channel_ready
    raise MilvusException(
pymilvus.exceptions.MilvusException: <MilvusException: (code=2, message=Fail connecting to server on localhost:19530, illegal connection params or server unavailable)>
[2025-08-08T15:04:00.495+0700] {taskinstance.py:1400} INFO - Marking task as FAILED. dag_id=ekstrak_pdf_dag, task_id=insert_to_milvus, execution_date=20250807T094930, start_date=20250808T080347, end_date=20250808T080400
[2025-08-08T15:04:00.536+0700] {standard_task_runner.py:104} ERROR - Failed to execute job 25 for task insert_to_milvus (<MilvusException: (code=2, message=Fail connecting to server on localhost:19530, illegal connection params or server unavailable)>; 88673)
[2025-08-08T15:04:00.559+0700] {local_task_job_runner.py:228} INFO - Task exited with return code 1
[2025-08-08T15:04:00.586+0700] {taskinstance.py:2778} INFO - 0 downstream tasks scheduled from follow-on schedule check
