[2025-08-07T15:54:38.783+0700] {taskinstance.py:1159} INFO - Dependencies all met for dep_context=non-requeueable deps ti=<TaskInstance: ekstrak_pdf_dag.chunk manual__2025-08-07T08:53:54.004426+00:00 [queued]>
[2025-08-07T15:54:38.793+0700] {taskinstance.py:1159} INFO - Dependencies all met for dep_context=requeueable deps ti=<TaskInstance: ekstrak_pdf_dag.chunk manual__2025-08-07T08:53:54.004426+00:00 [queued]>
[2025-08-07T15:54:38.794+0700] {taskinstance.py:1361} INFO - Starting attempt 1 of 1
[2025-08-07T15:54:38.844+0700] {taskinstance.py:1382} INFO - Executing <Task(PythonOperator): chunk> on 2025-08-07 08:53:54.004426+00:00
[2025-08-07T15:54:38.852+0700] {standard_task_runner.py:57} INFO - Started process 116066 to run task
[2025-08-07T15:54:38.858+0700] {standard_task_runner.py:84} INFO - Running: ['airflow', 'tasks', 'run', 'ekstrak_pdf_dag', 'chunk', 'manual__2025-08-07T08:53:54.004426+00:00', '--job-id', '5', '--raw', '--subdir', 'DAGS_FOLDER/etl.py', '--cfg-path', '/tmp/tmp5p_6bu1h']
[2025-08-07T15:54:38.860+0700] {standard_task_runner.py:85} INFO - Job 5: Subtask chunk
[2025-08-07T15:54:38.970+0700] {task_command.py:416} INFO - Running <TaskInstance: ekstrak_pdf_dag.chunk manual__2025-08-07T08:53:54.004426+00:00 [running]> on host dwmhr.localdomain
[2025-08-07T15:54:39.105+0700] {taskinstance.py:1662} INFO - Exporting env vars: AIRFLOW_CTX_DAG_OWNER='airflow' AIRFLOW_CTX_DAG_ID='ekstrak_pdf_dag' AIRFLOW_CTX_TASK_ID='chunk' AIRFLOW_CTX_EXECUTION_DATE='2025-08-07T08:53:54.004426+00:00' AIRFLOW_CTX_TRY_NUMBER='1' AIRFLOW_CTX_DAG_RUN_ID='manual__2025-08-07T08:53:54.004426+00:00'
[2025-08-07T15:54:39.109+0700] {taskinstance.py:1937} ERROR - Task failed with exception
Traceback (most recent call last):
  File "/home/dwmhr/pln/venv/lib/python3.10/site-packages/airflow/operators/python.py", line 192, in execute
    return_value = self.execute_callable()
  File "/home/dwmhr/pln/venv/lib/python3.10/site-packages/airflow/operators/python.py", line 209, in execute_callable
    return self.python_callable(*self.op_args, **self.op_kwargs)
  File "/home/dwmhr/pln/scripts/chunking.py", line 53, in run_chunk
    from transformers import AutoTokenizer
ModuleNotFoundError: No module named 'transformers'
[2025-08-07T15:54:39.123+0700] {taskinstance.py:1400} INFO - Marking task as FAILED. dag_id=ekstrak_pdf_dag, task_id=chunk, execution_date=20250807T085354, start_date=20250807T085438, end_date=20250807T085439
[2025-08-07T15:54:39.149+0700] {standard_task_runner.py:104} ERROR - Failed to execute job 5 for task chunk (No module named 'transformers'; 116066)
[2025-08-07T15:54:39.197+0700] {local_task_job_runner.py:228} INFO - Task exited with return code 1
[2025-08-07T15:54:39.230+0700] {taskinstance.py:2778} INFO - 0 downstream tasks scheduled from follow-on schedule check
